Workbook
Name Simulations: Solataire!$C$3

Sheet Investment Decision
B10: Initial Investment | C10: 1000
B11: Initial Tenor | C11: 3
B15: Residual Rate Needed | C15: =J67 -> 0.032503891
B18: Tenor (yrs) | C18: Rate (apr)
B19: 1 | C19: 0.0475
B20: 2 | C20: 0.045
B21: 3 | C21: 0.045
B22: 4 | C22: 0.0425
B23: 5 | C23: 0.04
D52: Residual Rate Needed | G52: Tadj Rates | H52: Tadj NPER
C53: 1 | D53: 0.0381 | G53: =C19/$D$67 -> 0.0039583333 | H53: =B19*$D$67 -> 12 | I53: =FV(G53,H53,$D$68,$D$65) -> 1048.5479 | J53: =RATE($H$57-H53,$D$68,-I53,$J$61)*$D$67 -> 0.03812573
C54: 2 | D54: 0.0367 | G54: =C20/$D$67 -> 0.00375 | H54: =B20*$D$67 -> 24 | I54: =FV(G54,H54,$D$68,$D$65) -> 1093.9901 | J54: =RATE($H$57-H54,$D$68,-I54,$J$61)*$D$67 -> 0.03666782
C55: 3 | D55: 0.0325 | G55: =C21/$D$67 -> 0.00375 | H55: =B21*$D$67 -> 36 | I55: =FV(G55,H55,$D$68,$D$65) -> 1144.2478 | J55: =RATE($H$57-H55,$D$68,-I55,$J$61)*$D$67 -> 0.032503891
C56: 4 | D56: 0.03 | G56: =C22/$D$67 -> 0.0035416667 | H56: =B22*$D$67 -> 48 | I56: =FV(G56,H56,$D$68,$D$65) -> 1184.9489 | J56: =RATE($H$57-H56,$D$68,-I56,$J$61)*$D$67 -> 0.030005189
G57: =C23/$D$67 -> 0.0033333333 | H57: =B23*$D$67 -> 60 | I57: =FV(G57,H57,$D$68,$D$65) -> 1220.9966 | J57: //////////////////
J60: Value of Initial Investment after 5 years
J61: =FV(G57,H57,D68,D65) -> 1220.9966
J63: ="Value of $"&-D65&" after "&D66&" years at "&(E66*D67*100)&"%" -> Value of $1000 after 3 years at 4.5%
J64: =FV(E66,F66,D68,D65) -> 1144.2478
C65: Initial Investmmnet | D65: -1000
C66: Initial Tenor (yrs) | D66: =C11 -> 3 | E66: =_xlfn.XLOOKUP(D66,B19:B23,G53:G57) -> 0.00375 | F66: =_xlfn.XLOOKUP(D66,B19:B23,H53:H57) -> 36 | G66: =_xlfn.XLOOKUP(D66,B19:B23,J53:J57) -> 0.032503891 | J66: Residual Rate Needed
C67: Time Adjustment | D67: 12 | J67: =RATE(H57-F66,D68,-J64,J61)*D67 -> 0.032503891
C68: PMT | D68: 0

Sheet Probability to Cashflows
B5: Phase 1 | I5: Phase 2 | O5: Phase 3
P9: Total plays | Q9: =E51 -> 10000
I10: payout | J10: Expected Profit (per player) | P10: Total wins | Q10: =COUNTIF('Coin Flip'!Q9:Q10008,1) -> 359
I11: 500 | J11: =$E$49 - I11*$E$52 -> -8.32 | P11: Total losses | Q11: =Q9-Q10 -> 9641
I12: 550 | J12: =$E$49 - I12*$E$52 -> -10.152 | P12: Total profit | Q12: ='Coin Flip'!U10008 -> -259000
I13: 600 | J13: =$E$49 - I13*$E$52 -> -11.984 | P13: average profit per play | Q13: =Q12/Q9 -> -25.9
I14: 650 | J14: =$E$49 - I14*$E$52 -> -13.816
I15: 700 | J15: =$E$49 - I15*$E$52 -> -15.648
B16: Entry Fee | C16: 10 | E16: Win Probability | F16: ='Coin Flip'!C2 -> 0.03664 | I16: 750 | J16: =$E$49 - I16*$E$52 -> -17.48
B17: Payout | C17: 1000 | E17: Loss Probability | F17: =1-F16 -> 0.96336 | I17: 800 | J17: =$E$49 - I17*$E$52 -> -19.312
B18: Players This Run | C18: 10000 | I18: 850 | J18: =$E$49 - I18*$E$52 -> -21.144
I19: 900 | J19: =$E$49 - I19*$E$52 -> -22.976
I20: 950 | J20: =$E$49 - I20*$E$52 -> -24.808
I21: 1000 | J21: =$E$49 - I21*$E$52 -> -26.64
I22: 1050 | J22: =$E$49 - I22*$E$52 -> -28.472
I23: 1100 | J23: =$E$49 - I23*$E$52 -> -30.304
I24: 1150 | J24: =$E$49 - I24*$E$52 -> -32.136
I25: 1200 | J25: =$E$49 - I25*$E$52 -> -33.968
D49: Entry Fee | E49: 10
D50: Payout | E50: 1000
D51: Players This Run | E51: 10000
D52: win probability | E52: =F16 -> 0.03664
D53: EV (per player) | E53: =E49-E50*E52 -> -26.64
D54: break even point | E54: =E49/E50 -> 0.01
I58: payout | J58: EV (per player)
I59: 0 | J59: 0
I60: 50 | J60: 0
I61: 100 | J61: 0
I62: 150 | J62: 0
I63: 200 | J63: 0
I64: 250 | J64: 0
I65: 300 | J65: 0
I66: 350 | J66: 0
I67: 400 | J67: 0
I68: 450 | J68: 0
I69: 500 | J69: 0
I70: 550 | J70: 0
... I84: 1500 | J84: 0

Sheet Schedule
K8: Term | L8: 2024FAL | N8: Days | O8: Start Time | P8: End Time
N9: M | O9: 0.625 | P9: 0.75
K10: Meeting Days | L10: MWF | N10: T | O10: 0.66666667 | P10: 0.77083333
N11: W | O11: 0.6875 | P11: 0.77083333
K12: Subject 1 | L12: CIS | N12: R | O12: 0.66666667 | P12: 0.78125
K13: Subject 2 | L13: BIO | N13: F | O13: 0.66666667 | P13: 0.71875
K14: Subject 3 | L14: ECN
K19: Labs that Conflict | L19: =COUNTIF(Q54:Q64,"Yes") -> 7 | N19: CIS | O19: =SUM(H67:P67) -> 127
K20: Labs that Don’t Conflict | L20: =COUNTIF(Q54:Q64,"No") -> 4 | N20: BIO | O20: =SUM(H68:P68) -> 260
K21: Total Labs | L21: =L19+L20 -> 11 | N21: ECN | O21: =SUM(H69:P69) -> 135
K22: Percentage of Conflicts | L22: =L19/L21 -> 0.63636364
B38: Estimated Grade: 94/100
D43: Start Time | E43: Meeting Days
D44: 0.375 | E44: MWF | F44: =IF(E44=$L$10,D44,"") -> 0.375
D45: 0.43055556 | E45: MWF | F45: =IF(E45=$L$10,D45,"") -> 0.43055556 | AB45: I want to create a story of an athlete who is a cis major and is looking at some of the most common minors
D46: 0.48611111 | E46: MWF | F46: =IF(E46=$L$10,D46,"") -> 0.48611111 | AB46: they are going to be a freshman in their spring semester
D47: 0.54166667 | E47: MWF | F47: =IF(E47=$L$10,D47,"") -> 0.54166667 | AB47: just want to show the connection and how hard it is for an athlete to get the classes they want
D48: 0.59722222 | E48: MWF | F48: =IF(E48=$L$10,D48,"") -> 0.59722222
D49: 0.65277778 | E49: MWF | F49: =IF(E49=$L$10,D49,"") -> 0.65277778
D50: 0.33333333 | E50: TR | F50: =IF(E50=$L$10,D50,"") | AB50: Color cordinate it
D51: 0.375 | E51: TR | F51: =IF(E51=$L$10,D51,"") | AB51: Story needs to be in the top left
D52: 0.45486111 | E52: TR | F52: =IF(E52=$L$10,D52,"")
D53: 0.53472222 | E53: TR | F53: =IF(E53=$L$10,D53,"") | J53: Term | K53: Subject | L53: Course Number | M53: Short Title | N53: Lab Meeing Day | O53: Start Time | P53: End Time | Q53: conflict? | AB53: wants to see a sumifs function and a pivot table that does the same thing as the sumifs
D54: 0.54166667 | E54: TR | F54: =IF(E54=$L$10,D54,"") | J54: 2024FAL | K54: BIO | L54: 100L | M54: Intro to Bioinformatics - Lab | N54: R | O54: 0.54166667 | P54: 0.67708333 | Q54: =IF(OR(AND(N54=$N$9,O54<$P$9,P54>$O$9),AND(N54=$N$10,O54<$P$10,P54>$O$10),AND(N54=$N$11,O54<$P$11,P54>$O$11),AND(N54=$N$12,O54<$P$12,P54>$O$12),AND(N54=$N$13,O54<$P$13,P54>$O$13)),"Yes","No") -> Yes
D55: 0.61458333 | E55: TR | F55: =IF(E55=$L$10,D55,"") | J55: 2024FAL | K55: BIO | L55: 121L | M55: Foundations in Bio CMB Lab | N55: R | O55: 0.54166667 | P55: 0.67708333 | Q55: =IF(OR(AND(N55=$N$9,O55<$P$9,P55>$O$9),AND(N55=$N$10,O55<$P$10,P55>$O$10),AND(N55=$N$11,O55<$P$11,P55>$O$11),AND(N55=$N$12,O55<$P$12,P55>$O$12),AND(N55=$N$13,O55<$P$13,P55>$O$13)),"Yes","No") -> Yes
D56: 0.69444444 | E56: TR | F56: =IF(E56=$L$10,D56,"") | J56: 2024FAL | K56: BIO | L56: 103L | M56: Human Anat & Physiology I Lab | N56: R | O56: 0.58333333 | P56: 0.71875 | Q56: =IF(OR(AND(N56=$N$9,O56<$P$9,P56>$O$9),AND(N56=$N$10,O56<$P$10,P56>$O$10),AND(N56=$N$11,O56<$P$11,P56>$O$11),AND(N56=$N$12,O56<$P$12,P56>$O$12),AND(N56=$N$13,O56<$P$13,P56>$O$13)),"Yes","No") -> Yes | AD56: this is what the pivot table should look like
D57: 0.70833333 | E57: TR | F57: =IF(E57=$L$10,D57,"") | J57: 2024FAL | K57: BIO | L57: 121L | M57: Foundations in Bio CMB Lab | N57: R | O57: 0.375 | P57: 0.51041667 | Q57: =IF(OR(AND(N57=$N$9,O57<$P$9,P57>$O$9),AND(N57=$N$10,O57<$P$10,P57>$O$10),AND(N57=$N$11,O57<$P$11,P57>$O$11),AND(N57=$N$12,O57<$P$12,P57>$O$12),AND(N57=$N$13,O57<$P$13,P57>$O$13)),"Yes","No") -> No
D58: 0.72916667 | E58: TR | F58: =IF(E58=$L$10,D58,"") | J58: 2024FAL | K58: BIO | L58: 111L | M58: Foundations in Bio EBD Lab | N58: T | O58: 0.54166667 | P58: 0.67708333 | Q58: =IF(OR(AND(N58=$N$9,O58<$P$9,P58>$O$9),AND(N58=$N$10,O58<$P$10,P58>$O$10),AND(N58=$N$11,O58<$P$11,P58>$O$11),AND(N58=$N$12,O58<$P$12,P58>$O$12),AND(N58=$N$13,O58<$P$13,P58>$O$13)),"Yes","No") -> Yes | AD58: term | AE58: fal
D59: 0.83333333 | E59: TR | F59: =IF(E59=$L$10,D59,"") | J59: 2024FAL | K59: BIO | L59: 121L | M59: Foundations in Bio CMB Lab | N59: T | O59: 0.54166667 | P59: 0.67708333 | Q59: =IF(OR(AND(N59=$N$9,O59<$P$9,P59>$O$9),AND(N59=$N$10,O59<$P$10,P59>$O$10),AND(N59=$N$11,O59<$P$11,P59>$O$11),AND(N59=$N$12,O59<$P$12,P59>$O$12),AND(N59=$N$13,O59<$P$13,P59>$O$13)),"Yes","No") -> Yes | AD59: days | AE59: mwf
D60: 0.33333333 | E60: Other | F60: =IF(E60=$L$10,D60,"") | J60: 2024FAL | K60: BIO | L60: 103L | M60: Human Anat & Physiology I Lab | N60: T | O60: 0.58333333 | P60: 0.71875 | Q60: =IF(OR(AND(N60=$N$9,O60<$P$9,P60>$O$9),AND(N60=$N$10,O60<$P$10,P60>$O$10),AND(N60=$N$11,O60<$P$11,P60>$O$11),AND(N60=$N$12,O60<$P$12,P60>$O$12),AND(N60=$N$13,O60<$P$13,P60>$O$13)),"Yes","No") -> Yes
D61: 0.375 | E61: Other | F61: =IF(E61=$L$10,D61,"") | J61: 2024FAL | K61: BIO | L61: 111L | M61: Foundations in Bio EBD Lab | N61: T | O61: 0.33333333 | P61: 0.46875 | Q61: =IF(OR(AND(N61=$N$9,O61<$P$9,P61>$O$9),AND(N61=$N$10,O61<$P$10,P61>$O$10),AND(N61=$N$11,O61<$P$11,P61>$O$11),AND(N61=$N$12,O61<$P$12,P61>$O$12),AND(N61=$N$13,O61<$P$13,P61>$O$13)),"Yes","No") -> No | AD61: rows lables | AE61: sum of capacity
D62: 0.45486111 | E62: Other | F62: =IF(E62=$L$10,D62,"") | J62: 2024FAL | K62: BIO | L62: 121L | M62: Foundations in Bio CMB Lab | N62: T | O62: 0.375 | P62: 0.51041667 | Q62: =IF(OR(AND(N62=$N$9,O62<$P$9,P62>$O$9),AND(N62=$N$10,O62<$P$10,P62>$O$10),AND(N62=$N$11,O62<$P$11,P62>$O$11),AND(N62=$N$12,O62<$P$12,P62>$O$12),AND(N62=$N$13,O62<$P$13,P62>$O$13)),"Yes","No") -> No | AF62: could put the sum ifs here
D63: 0.53472222 | E63: Other | F63: =IF(E63=$L$10,D63,"") | J63: 2024FAL | K63: BIO | L63: 121L | M63: Foundations in Bio CMB Lab | N63: W | O63: 0.59722222 | P63: 0.73263889 | Q63: =IF(OR(AND(N63=$N$9,O63<$P$9,P63>$O$9),AND(N63=$N$10,O63<$P$10,P63>$O$10),AND(N63=$N$11,O63<$P$11,P63>$O$11),AND(N63=$N$12,O63<$P$12,P63>$O$12),AND(N63=$N$13,O63<$P$13,P63>$O$13)),"Yes","No") -> Yes
D64: 0.54166667 | E64: Other | F64: =IF(E64=$L$10,D64,"") | J64: 2024FAL | K64: BIO | L64: 103L | M64: Human Anat & Physiology I Lab | N64: W | O64: 0.33333333 | P64: 0.46875 | Q64: =IF(OR(AND(N64=$N$9,O64<$P$9,P64>$O$9),AND(N64=$N$10,O64<$P$10,P64>$O$10),AND(N64=$N$11,O64<$P$11,P64>$O$11),AND(N64=$N$12,O64<$P$12,P64>$O$12),AND(N64=$N$13,O64<$P$13,P64>$O$13)),"Yes","No") -> No
D65: 0.61458333 | E65: Other | F65: =IF(E65=$L$10,D65,"")
D66: 0.69444444 | E66: Other | F66: =IF(E66=$L$10,D66,"") | H66: =SMALL($F$44:$F$69,H75) -> 0.375 | I66: =SMALL($F$44:$F$69,I75) -> 0.43055556 | J66: =SMALL($F$44:$F$69,J75) -> 0.48611111 | K66: =SMALL($F$44:$F$69,K75) -> 0.54166667 | L66: =SMALL($F$44:$F$69,L75) -> 0.59722222 | M66: =SMALL($F$44:$F$69,M75) -> 0.65277778 | N66: =SMALL($F$44:$F$69,N75) -> #NUM! | O66: =SMALL($F$44:$F$69,O75) -> #NUM! | P66: =SMALL($F$44:$F$69,P75) -> #NUM!
D67: 0.70833333 | E67: Other | F67: =IF(E67=$L$10,D67,"") | G67: CIS | H67: =SUMIFS('CourseBook Values'!$AD:$AD,'CourseBook Values'!$A:$A,"="&$L$8,'CourseBook Values'!$W:$W,"="&$L$10,'CourseBook Values'!$B:$B,"="&$L12,'CourseBook Values'!$Y:$Y,"="&Schedule!H$66) -> 36 | I67: =SUMIFS('CourseBook Values'!$AD:$AD,'CourseBook Values'!$A:$A,"="&$L$8,'CourseBook Values'!$W:$W,"="&$L$10,'CourseBook Values'!$B:$B,"="&$L12,'CourseBook Values'!$Y:$Y,"="&Schedule!I$66) -> 33 | J67: =SUMIFS('CourseBook Values'!$AD:$AD,'CourseBook Values'!$A:$A,"="&$L$8,'CourseBook Values'!$W:$W,"="&$L$10,'CourseBook Values'!$B:$B,"="&$L12,'CourseBook Values'!$Y:$Y,"="&Schedule!J$66) -> 0 | K67: =SUMIFS('CourseBook Values'!$AD:$AD,'CourseBook Values'!$A:$A,"="&$L$8,'CourseBook Values'!$W:$W,"="&$L$10,'CourseBook Values'!$B:$B,"="&$L12,'CourseBook Values'!$Y:$Y,"="&Schedule!K$66) -> 58 | L67: =SUMIFS('CourseBook Values'!$AD:$AD,'CourseBook Values'!$A:$A,"="&$L$8,'CourseBook Values'!$W:$W,"="&$L$10,'CourseBook Values'!$B:$B,"="&$L12,'CourseBook Values'!$Y:$Y,"="&Schedule!L$66) -> 0 | M67: =SUMIFS('CourseBook Values'!$AD:$AD,'CourseBook Values'!$A:$A,"="&$L$8,'CourseBook Values'!$W:$W,"="&$L$10,'CourseBook Values'!$B:$B,"="&$L12,'CourseBook Values'!$Y:$Y,"="&Schedule!M$66) -> 0 | N67: =SUMIFS('CourseBook Values'!$AD:$AD,'CourseBook Values'!$A:$A,"="&$L$8,'CourseBook Values'!$W:$W,"="&$L$10,'CourseBook Values'!$B:$B,"="&$L12,'CourseBook Values'!$Y:$Y,"="&Schedule!N$66) -> 0 | O67: =SUMIFS('CourseBook Values'!$AD:$AD,'CourseBook Values'!$A:$A,"="&$L$8,'CourseBook Values'!$W:$W,"="&$L$10,'CourseBook Values'!$B:$B,"="&$L12,'CourseBook Values'!$Y:$Y,"="&Schedule!O$66) -> 0 | P67: =SUMIFS('CourseBook Values'!$AD:$AD,'CourseBook Values'!$A:$A,"="&$L$8,'CourseBook Values'!$W:$W,"="&$L$10,'CourseBook Values'!$B:$B,"="&$L12,'CourseBook Values'!$Y:$Y,"="&Schedule!P$66) -> 0
D68: 0.72916667 | E68: Other | F68: =IF(E68=$L$10,D68,"") | G68: BIO | H68: =SUMIFS('CourseBook Values'!$AD:$AD,'CourseBook Values'!$A:$A,"="&$L$8,'CourseBook Values'!$W:$W,"="&$L$10,'CourseBook Values'!$B:$B,"="&$L13,'CourseBook Values'!$Y:$Y,"="&Schedule!H$66) -> 75 | I68: =SUMIFS('CourseBook Values'!$AD:$AD,'CourseBook Values'!$A:$A,"="&$L$8,'CourseBook Values'!$W:$W,"="&$L$10,'CourseBook Values'!$B:$B,"="&$L13,'CourseBook Values'!$Y:$Y,"="&Schedule!I$66) -> 77 | J68: =SUMIFS('CourseBook Values'!$AD:$AD,'CourseBook Values'!$A:$A,"="&$L$8,'CourseBook Values'!$W:$W,"="&$L$10,'CourseBook Values'!$B:$B,"="&$L13,'CourseBook Values'!$Y:$Y,"="&Schedule!J$66) -> 52 | K68: =SUMIFS('CourseBook Values'!$AD:$AD,'CourseBook Values'!$A:$A,"="&$L$8,'CourseBook Values'!$W:$W,"="&$L$10,'CourseBook Values'!$B:$B,"="&$L13,'CourseBook Values'!$Y:$Y,"="&Schedule!K$66) -> 56 | L68: =SUMIFS('CourseBook Values'!$AD:$AD,'CourseBook Values'!$A:$A,"="&$L$8,'CourseBook Values'!$W:$W,"="&$L$10,'CourseBook Values'!$B:$B,"="&$L13,'CourseBook Values'!$Y:$Y,"="&Schedule!L$66) -> 0 | M68: =SUMIFS('CourseBook Values'!$AD:$AD,'CourseBook Values'!$A:$A,"="&$L$8,'CourseBook Values'!$W:$W,"="&$L$10,'CourseBook Values'!$B:$B,"="&$L13,'CourseBook Values'!$Y:$Y,"="&Schedule!M$66) -> 0 | N68: =SUMIFS('CourseBook Values'!$AD:$AD,'CourseBook Values'!$A:$A,"="&$L$8,'CourseBook Values'!$W:$W,"="&$L$10,'CourseBook Values'!$B:$B,"="&$L13,'CourseBook Values'!$Y:$Y,"="&Schedule!N$66) -> 0 | O68: =SUMIFS('CourseBook Values'!$AD:$AD,'CourseBook Values'!$A:$A,"="&$L$8,'CourseBook Values'!$W:$W,"="&$L$10,'CourseBook Values'!$B:$B,"="&$L13,'CourseBook Values'!$Y:$Y,"="&Schedule!O$66) -> 0 | P68: =SUMIFS('CourseBook Values'!$AD:$AD,'CourseBook Values'!$A:$A,"="&$L$8,'CourseBook Values'!$W:$W,"="&$L$10,'CourseBook Values'!$B:$B,"="&$L13,'CourseBook Values'!$Y:$Y,"="&Schedule!P$66) -> 0
D69: 0.83333333 | E69: Other | F69: =IF(E69=$L$10,D69,"") | G69: ECN | H69: =SUMIFS('CourseBook Values'!$AD:$AD,'CourseBook Values'!$A:$A,"="&$L$8,'CourseBook Values'!$W:$W,"="&$L$10,'CourseBook Values'!$B:$B,"="&$L14,'CourseBook Values'!$Y:$Y,"="&Schedule!H$66) -> 35 | I69: =SUMIFS('CourseBook Values'!$AD:$AD,'CourseBook Values'!$A:$A,"="&$L$8,'CourseBook Values'!$W:$W,"="&$L$10,'CourseBook Values'!$B:$B,"="&$L14,'CourseBook Values'!$Y:$Y,"="&Schedule!I$66) -> 35 | J69: =SUMIFS('CourseBook Values'!$AD:$AD,'CourseBook Values'!$A:$A,"="&$L$8,'CourseBook Values'!$W:$W,"="&$L$10,'CourseBook Values'!$B:$B,"="&$L14,'CourseBook Values'!$Y:$Y,"="&Schedule!J$66) -> 45 | K69: =SUMIFS('CourseBook Values'!$AD:$AD,'CourseBook Values'!$A:$A,"="&$L$8,'CourseBook Values'!$W:$W,"="&$L$10,'CourseBook Values'!$B:$B,"="&$L14,'CourseBook Values'!$Y:$Y,"="&Schedule!K$66) -> 20 | L69: =SUMIFS('CourseBook Values'!$AD:$AD,'CourseBook Values'!$A:$A,"="&$L$8,'CourseBook Values'!$W:$W,"="&$L$10,'CourseBook Values'!$B:$B,"="&$L14,'CourseBook Values'!$Y:$Y,"="&Schedule!L$66) -> 0 | M69: =SUMIFS('CourseBook Values'!$AD:$AD,'CourseBook Values'!$A:$A,"="&$L$8,'CourseBook Values'!$W:$W,"="&$L$10,'CourseBook Values'!$B:$B,"="&$L14,'CourseBook Values'!$Y:$Y,"="&Schedule!M$66) -> 0 | N69: =SUMIFS('CourseBook Values'!$AD:$AD,'CourseBook Values'!$A:$A,"="&$L$8,'CourseBook Values'!$W:$W,"="&$L$10,'CourseBook Values'!$B:$B,"="&$L14,'CourseBook Values'!$Y:$Y,"="&Schedule!N$66) -> 0 | O69: =SUMIFS('CourseBook Values'!$AD:$AD,'CourseBook Values'!$A:$A,"="&$L$8,'CourseBook Values'!$W:$W,"="&$L$10,'CourseBook Values'!$B:$B,"="&$L14,'CourseBook Values'!$Y:$Y,"="&Schedule!O$66) -> 0 | P69: =SUMIFS('CourseBook Values'!$AD:$AD,'CourseBook Values'!$A:$A,"="&$L$8,'CourseBook Values'!$W:$W,"="&$L$10,'CourseBook Values'!$B:$B,"="&$L14,'CourseBook Values'!$Y:$Y,"="&Schedule!P$66) -> 0
H75: 1 | I75: 2 | J75: 3 | K75: 4 | L75: 5 | M75: 6 | N75: 7 | O75: 8 | P75: 9
...

Sheet CFI Exercises
B3: IF with AND
B5: Data Cell | C5: 150
B7: Condition 1 | C7: 100 | D7: >=
B8: Condition 2 | C8: 999 | D8: <=
B9: Result if True | C9: 100
B10: Result if False | C10: 0
B12: Live Formula | C12: =IF(AND(C5>=C7,C5<=C8),C9,C10) -> 100 | D12: =_xlfn.FORMULATEXT(C12) -> =IF(AND(C5>=C7,C5<=C8),C9,C10)
B14: Alternative Formula | C14: =IF((C5>=C7)*(C5<=C8),C9,C10) -> 100 | D14: =_xlfn.FORMULATEXT(C14) -> =IF((C5>=C7)*(C5<=C8),C9,C10)
B16: Simple If 1 | C16: =IF(C7>=C8,1,0) -> 0
B18: Simple If 2 | C18: =IF(C5<=C8,1,0) -> 1
B21: IF with OR
B23: Data Cell | C23: 150
B25: Condition 1 | C25: 100 | D25: >=
B26: Condition 2 | C26: 999 | D26: <=
B27: Result if True | C27: 100
B28: Result if False | C28: 0
B30: Live Formula | C30: =IF(OR(C23>=C25,C23<=C26),C27,C28) -> 100 | D30: =_xlfn.FORMULATEXT(C30) -> =IF(OR(C23>=C25,C23<=C26),C27,C28)
B32: Simple If 1 | C32: =IF(C23>=C24,1,0) -> 1
B34: Simple If 2 | C34: =IF(C21<=C24,1,0) -> 1
B39: OFFSET combined with SUM
B41: Offset Column Input | C41: 3
B42: Offset Row Input | C42: 0
C44: Numbers to Sum
C45: 5 | D45: 8 | E45: 2 | F45: 9 | G45: 6 | H45: 4
B47: Simple Sum | C47: =SUM(C45:E45) -> 15 | D47: =_xlfn.FORMULATEXT(C47) -> =SUM(C45:E45)
B49: Offset Sum | C49: =SUM(C45:OFFSET(C45,C42,C41-1)) -> 15 | D49: =_xlfn.FORMULATEXT(C49) -> =SUM(C45:OFFSET(C45,C42,C41-1))
B53: OFFSET combined with Average
B55: Offset Column Input | C55: 6
B56: Offset Row Input | C56: 7
C58: Numbers to Sum
C59: 5 | D59: 8 | E59: 2 | F59: 9 | G59: 6 | H59: 4
C60: 3 | D60: 3 | E60: 8 | F60: 1 | G60: 1 | H60: 8
C61: 6 | D61: 4 | E61: 5 | F61: 4 | G61: 9 | H61: 7
C62: 2 | D62: 10 | E62: 7 | F62: 9 | G62: 9 | H62: 7
C63: 4 | D63: 8 | E63: 1 | F63: 3 | G63: 8 | H63: 2
C64: 5 | D64: 4 | E64: 4 | F64: 6 | G64: 2 | H64: 8
C65: 10 | D65: 5 | E65: 3 | F65: 5 | G65: 9 | H65: 4
B67: Simple Average | C67: =AVERAGE(C59:H65) -> 5.4285714 | D67: =_xlfn.FORMULATEXT(C67) -> =AVERAGE(C59:H65)
B69: Offset Average | C69: =AVERAGE(C59:OFFSET(C59,C56-1,C55-1)) -> 5.4285714 | D69: =_xlfn.FORMULATEXT(C69) -> =AVERAGE(C59:OFFSET(C59,C56-1,C55-1))
M70: On test
...

Sheet Pivot Table
A1: Term | B1: 2024FAL
A2: Days | B2: MWF
A4: Row Labels | B4: Sum of Capacity | C4: SumIf Function used
A5: BIO | B5: 260 | C5: =SUMIFS('CourseBook Values'!$AD:$AD, 'CourseBook Values'!$A:$A, $B$1, 'CourseBook Values'!$W:$W, $B$2, 'CourseBook Values'!$B:$B, A5) -> 260 | D5: =_xlfn.FORMULATEXT(C5) -> =SUMIFS('CourseBook Values'!$AD:$AD, 'CourseBook Values'!$A:$A, $B$1, 'CourseBook Values'!$W:$W, $B$2, 'CourseBook Values'!$B:$B, A5)
A6: CIS | B6: 127 | C6: =SUMIFS('CourseBook Values'!$AD:$AD, 'CourseBook Values'!$A:$A, $B$1, 'CourseBook Values'!$W:$W, $B$2, 'CourseBook Values'!$B:$B, A6) -> 127 | D6: =_xlfn.FORMULATEXT(C6) -> =SUMIFS('CourseBook Values'!$AD:$AD, 'CourseBook Values'!$A:$A, $B$1, 'CourseBook Values'!$W:$W, $B$2, 'CourseBook Values'!$B:$B, A6)
A7: ECN | B7: 135 | C7: =SUMIFS('CourseBook Values'!$AD:$AD, 'CourseBook Values'!$A:$A, $B$1, 'CourseBook Values'!$W:$W, $B$2, 'CourseBook Values'!$B:$B, A7) -> 135 | D7: =_xlfn.FORMULATEXT(C7) -> =SUMIFS('CourseBook Values'!$AD:$AD, 'CourseBook Values'!$A:$A, $B$1, 'CourseBook Values'!$W:$W, $B$2, 'CourseBook Values'!$B:$B, A7)
A8: Grand Total | B8: 522
D14: s

Sheet CourseBook Values
A1: Term | B1: Subject | C1: Course Number | D1: Section | E1: Short Title | F1: Sec Min Cred | G1: First Faculty Last Name | H1: First Faculty First Name | I1: Second Faculty Last Name | J1: Second Faculty First Name | K1: 1st Fac | L1: 2nd Fac | M1: Meeting Days | N1: M | O1: T | P1: W | Q1: R | R1: F | S1: MWF | T1: TR | U1: Other | V1: Lab Meeing Day | W1: Days | X1: Sec Meeting Info Time | Y1: Start Time | Z1: End Time | AA1: Building | AB1: ROOM | AC1: Start/End Date Bldg Room Meth Days Start/End time | AD1: Capacity | AE1: Active Student Count | AF1: Cross-Listed Course Sections | AG1: Lab or not
A2: 2024FAL | B2: BIO | C2: 205 | D2: 01 | E2: Invertebrate Zoology | F2: 4 | G2: March | H2: James | K2: MarchJames | M2: M | N2: 1 | U2: 1 | W2: =IF(S2=1,"MWF",IF(T2=1,"TR","Other")) -> Other | X2: 02:20PM - 05:35PM | Y2: 0.59722222 | Z2: 0.73263889 | AA2: D-P | AB2: 109 | AC2: 08/27/24 12/16/24 D-P 109 LEC M 02:20PM 05:35PM | AD2: 10 | AE2: 14 | AG2: =IF(RIGHT(C2,1)="L","Lab","Non-Lab") -> Non-Lab
A3: 2024FAL | B3: BIO | C3: 212L | D3: 01 | E3: Cell Biology - Lab | F3: 0 | G3: DeBerry | H3: Candy | K3: DeBerryCandy | M3: M | N3: 1 | U3: 1 | V3: =LEFT(M3,1) -> M | W3: =IF(S3=1,"MWF",IF(T3=1,"TR","Other")) -> Other | X3: 02:20PM - 05:35PM | Y3: 0.59722222 | Z3: 0.73263889 | AA3: D-P | AB3: 102 | AC3: 08/27/24 12/16/24 D-P 102 LAB M 02:20PM 05:35PM | AD3: 15 | AE3: 7 | AG3: =IF(RIGHT(C3,1)="L","Lab","Non-Lab") -> Lab
A4: 2024FAL | B4: PHY | C4: 100L | D4: 01 | E4: Introduction to Physics Lab | F4: 0 | G4: Chamberlin | H4: Sara | K4: ChamberlinSara | M4: M | N4: 1 | U4: 1 | V4: =LEFT(M4,1) -> M | W4: =IF(S4=1,"MWF",IF(T4=1,"TR","Other")) -> Other | X4: 02:20PM - 05:35PM | Y4: 0.59722222 | Z4: 0.73263889 | AA4: SWA | AB4: 112 | AC4: 08/27/24 12/16/24 SWA 112 LAB M 02:20PM 05:35PM | AD4: 17 | AE4: 12 | AG4: =IF(RIGHT(C4,1)="L","Lab","Non-Lab") -> Lab
A5: 2024FAL | B5: COM | C5: 242 | D5: 01 | E5: Radio Performance or Product | F5: 1 | G5: Maradin | H5: Nicholas | K5: MaradinNicholas | M5: M | N5: 1 | U5: 1 | W5: =IF(S5=1,"MWF",IF(T5=1,"TR","Other")) -> Other | X5: 04:15PM - 05:15PM | Y5: 0.67708333 | Z5: 0.71875 | AA5: BUR | AB5: 003 | AC5: 08/27/24 12/16/24 BUR 003 LEC M 04:15PM 05:15PM | AD5: 8 | AE5: 8 | AG5: =IF(RIGHT(C5,1)="L","Lab","Non-Lab") -> Non-Lab
A6: 2024FAL | B6: EDU | C6: 350 | D6: 01 | E6: Teaching Multilingual Learner | F6: 4 | G6: Nelson | H6: Kristin | I6: Day | J6: Diane | K6: NelsonKristin | L6: DayDiane | M6: M | N6: 1 | U6: 1 | W6: =IF(S6=1,"MWF",IF(T6=1,"TR","Other")) -> Other | X6: 04:30PM - 08:10PM | Y6: 0.6875 | Z6: 0.84027778 | AA6: BUR | AB6: 023 | AC6: 08/27/24 12/16/24 BUR 023 LEC M 04:30PM 08:10PM | AD6: 10 | AE6: 16 | AG6: =IF(RIGHT(C6,1)="L","Lab","Non-Lab") -> Non-Lab
A7: 2024FAL | B7: NUR | C7: 050 | D7: 01 | E7: Pre-Nursing Seminar I | F7: 1 | G7: Edwards-Doe | H7: Linda | K7: Edwards-DoeLinda | M7: M | N7: 1 | U7: 1 | W7: =IF(S7=1,"MWF",IF(T7=1,"TR","Other")) -> Other | X7: 07:40AM - 08:50AM | Y7: 0.31944444 | Z7: 0.36805556 | AA7: D-P | AB7: 106 | AC7: 08/27/24 12/16/24 D-P 106 LEC M 07:40AM 08:50AM | AD7: 32 | AE7: 37 | AG7: =IF(RIGHT(C7,1)="L","Lab","Non-Lab") -> Non-Lab
A8: 2024FAL | B8: CHM | C8: 102L | D8: 01 | E8: Chemistry of Brewing Lab | F8: 0 | G8: Iuliucci | H8: Robbie | K8: IuliucciRobbie | M8: M, M | N8: 1 | U8: 1 | V8: =LEFT(M8,1) -> M | W8: =IF(S8=1,"MWF",IF(T8=1,"TR","Other")) -> Other | X8: 02:20PM - 05:35PM | Y8: 0.59722222 | Z8: 0.73263889 | AA8: SWA, SWA | AB8: 207, 208 | AC8: 08/27/24 12/16/24 SWA 207 LAB M 02:20PM 05:35PM, 08/27/24 12/16/24 SWA 208 LAB M 02:20PM 05:35PM | AD8: 0 | AE8: 16 | AG8: =IF(RIGHT(C8,1)="L","Lab","Non-Lab") -> Lab
A9: 2024FAL | B9: CHM | C9: 160L | D9: 05 | E9: Organic Chemistry Lab | F9: 0 | G9: Matsuno | H9: Nobunaka | K9: MatsunoNobunaka | M9: M, M | N9: 1 | U9: 1 | V9: =LEFT(M9,1) -> M | W9: =IF(S9=1,"MWF",IF(T9=1,"TR","Other")) -> Other | X9: 02:20PM - 05:35PM | Y9: 0.59722222 | Z9: 0.73263889 | AA9: SWA, SWA | AB9: 308, 307 | AC9: 08/27/24 12/16/24 SWA 308 LAB M 02:20PM 05:35PM, 08/27/24 12/16/24 SWA 307 LAB M 02:20PM 05:35PM | AD9: 13 | AE9: 11 | AG9: =IF(RIGHT(C9,1)="L","Lab","Non-Lab") -> Lab
A10: 2024FAL | B10: PHW | C10: 143 | D10: 01 | E10: Mindfulness in Music | F10: 2 | G10: Spadaro | H10: Patricia | I10: Glock | J10: Carol | K10: SpadaroPatricia | L10: GlockCarol | M10: M, W | N10: 1 | P10: 1 | U10: 1 | W10: =IF(S10=1,"MWF",IF(T10=1,"TR","Other")) -> Other | X10: 01:00PM - 02:00PM | Y10: 0.54166667 | Z10: 0.58333333 | AA10: REC | AB10: 304 | AC10: 08/27/24 12/16/24 REC 304 ACT MW 01:00PM 02:00PM | AD10: 18 | AE10: 17 | AG10: =IF(RIGHT(C10,1)="L","Lab","Non-Lab") -> Non-Lab
A11: 2024FAL | B11: ART | C11: 108 | D11: 01 | E11: 2-D & 3-D Design | F11: 4 | G11: Schmidt | H11: Patrick | K11: SchmidtPatrick | M11: M, W | N11: 1 | P11: 1 | U11: 1 | W11: =IF(S11=1,"MWF",IF(T11=1,"TR","Other")) -> Other | X11: 01:00PM - 04:00PM | Y11: 0.54166667 | Z11: 0.66666667 | AA11: OLN | AB11: 220 | AC11: 08/27/24 12/16/24 OLN 220 STU MW 01:00PM 04:00PM | AD11: 10 | AE11: 11 | AG11: =IF(RIGHT(C11,1)="L","Lab","Non-Lab") -> Non-Lab
A12: 2024FAL | B12: ART | C12: 361 | D12: 01 | E12: Ceramics Studio I | F12: 4 | G12: Alamilla | H12: Carolina | K12: AlamillaCarolina | M12: M, W | N12: 1 | P12: 1 | U12: 1 | W12: =IF(S12=1,"MWF",IF(T12=1,"TR","Other")) -> Other | X12: 01:00PM - 04:00PM | Y12: 0.54166667 | Z12: 0.66666667 | AA12: OLN | AB12: 120 | AC12: 08/27/24 12/16/24 OLN 120 STU MW 01:00PM 04:00PM | AD12: 5 | AE12: 7 | AG12: =IF(RIGHT(C12,1)="L","Lab","Non-Lab") -> Non-Lab
A13: 2024FAL | B13: ART | C13: 461 | D13: 01 | E13: Ceramics Studio II | F13: 4 | G13: Alamilla | H13: Carolina | K13: AlamillaCarolina | M13: M, W | N13: 1 | P13: 1 | U13: 1 | W13: =IF(S13=1,"MWF",IF(T13=1,"TR","Other")) -> Other | X13: 01:00PM - 04:00PM | Y13: 0.54166667 | Z13: 0.66666667 | AA13: OLN | AB13: 120 | AC13: 08/27/24 12/16/24 OLN 120 STU MW 01:00PM 04:00PM | AD13: 5 | AE13: 4 | AG13: =IF(RIGHT(C13,1)="L","Lab","Non-Lab") -> Non-Lab
A14: 2024FAL | B14: ACC | C14: 353 | D14: 01 | E14: Taxation of Business Entities | F14: 4 | G14: Mialki | H14: Dana | K14: MialkiDana | M14: M, W | N14: 1 | P14: 1 | U14: 1 | W14: =IF(S14=1,"MWF",IF(T14=1,"TR","Other")) -> Other | X14: 02:20PM - 04:05PM | Y14: 0.59722222 | Z14: 0.67013889 | AA14: BUR | AB14: 307 | AC14: 08/27/24 12/16/24 BUR 307 LEC MW 02:20PM 04:05PM | AD14: 30 | AE14: 32 | AG14: =IF(RIGHT(C14,1)="L","Lab","Non-Lab") -> Non-Lab
A15: 2024FAL | B15: COM | C15: 103 | D15: 01 | E15: Introduction to Media Studies | F15: 4 | G15: Maradin | H15: Nicholas | K15: MaradinNicholas | M15: M, W | N15: 1 | P15: 1 | U15: 1 | W15: =IF(S15=1,"MWF",IF(T15=1,"TR","Other")) -> Other | X15: 02:20PM - 04:05PM | Y15: 0.59722222 | Z15: 0.67013889 | AA15: BUR | AB15: 016 | AC15: 08/27/24 12/16/24 BUR 016 LEC MW 02:20PM 04:05PM | AD15: 24 | AE15: 23 | AG15: =IF(RIGHT(C15,1)="L","Lab","Non-Lab") -> Non-Lab
A16: 2024FAL | B16: COM | C16: 301 | D16: 01 | E16: Research Methods in Com Arts | F16: 4 | G16: Berberick | H16: Stevie | K16: BerberickStevie | M16: M, W | N16: 1 | P16: 1 | U16: 1 | W16: =IF(S16=1,"MWF",IF(T16=1,"TR","Other")) -> Other | X16: 02:20PM - 04:05PM | Y16: 0.59722222 | Z16: 0.67013889 | AA16: BUR | AB16: 003 | AC16: 08/27/24 12/16/24 BUR 003 LEC MW 02:20PM 04:05PM | AD16: 10 | AE16: 14 | AG16: =IF(RIGHT(C16,1)="L","Lab","Non-Lab") -> Non-Lab
A17: 2024FAL | B17: ECN | C17: 326 | D17: 01 | E17: Economics of Poverty & Discrim | F17: 4 | G17: Gottschall | H17: Tiffani | K17: GottschallTiffani | M17: M, W | N17: 1 | P17: 1 | U17: 1 | W17: =IF(S17=1,"MWF",IF(T17=1,"TR","Other")) -> Other | X17: 02:20PM - 04:05PM | Y17: 0.59722222 | Z17: 0.67013889 | AA17: BUR | AB17: 311 | AC17: 08/27/24 12/16/24 BUR 311 LEC MW 02:20PM 04:05PM | AD17: 20 | AE17: 20 | AG17: =IF(RIGHT(C17,1)="L","Lab","Non-Lab") -> Non-Lab
A18: 2024FAL | B18: ENG | C18: 111 | D18: 01 | E18: Composition | F18: 4 | G18: Gutierrez-Neal | H18: Pax | K18: Gutierrez-NealPax | M18: M, W | N18: 1 | P18: 1 | U18: 1 | W18: =IF(S18=1,"MWF",IF(T18=1,"TR","Other")) -> Other | X18: 02:20PM - 04:05PM | Y18: 0.59722222 | Z18: 0.67013889 | AA18: TEK | AB18: 103A | AC18: 08/27/24 12/16/24 TEK 103A DSC MW 02:20PM 04:05PM | AD18: 16 | AE18: 15 | AG18: =IF(RIGHT(C18,1)="L","Lab","Non-Lab") -> Non-Lab
A19: 2024FAL | B19: FIN | C19: 446 | D19: 01 | E19: Security Analysis & Valuation | F19: 4 | G19: Park | H19: Keun Jae | K19: ParkKeun Jae | M19: M, W | N19: 1 | P19: 1 | U19: 1 | W19: =IF(S19=1,"MWF",IF(T19=1,"TR","Other")) -> Other | X19: 02:20PM - 04:05PM | Y19: 0.59722222 | Z19: 0.67013889 | AA19: BUR | AB19: 109 | AC19: 08/27/24 12/16/24 BUR 109 LEC MW 02:20PM 04:05PM | AD19: 20 | AE19: 6 | AG19: =IF(RIGHT(C19,1)="L","Lab","Non-Lab") -> Non-Lab
A20: 2024FAL | B20: HIS | C20: 315 | D20: 01 | E20: Fighting Over the Past | F20: 4 | G20: Lanzillotti | H20: Ian | K20: LanzillottiIan | M20: M, W | N20: 1 | P20: 1 | U20: 1 | W20: =IF(S20=1,"MWF",IF(T20=1,"TR","Other")) -> Other | X20: 02:20PM - 04:05PM | Y20: 0.59722222 | Z20: 0.67013889 | AA20: BUR | AB20: 302 | AC20: 08/27/24 12/16/24 BUR 302 DSC MW 02:20PM 04:05PM | AD20: 15 | AE20: 11 | AG20: =IF(RIGHT(C20,1)="L","Lab","Non-Lab") -> Non-Lab
A21: 2024FAL | B21: PHL | C21: 112 | D21: 01 | E21: Argument Mapping | F21: 4 | G21: Kim | H21: Hanna | K21: KimHanna | M21: M, W | N21: 1 | P21: 1 | U21: 1 | W21: =IF(S21=1,"MWF",IF(T21=1,"TR","Other")) -> Other | X21: 02:20PM - 04:05PM | Y21: 0.59722222 | Z21: 0.67013889 | AA21: MAI | AB21: B | AC21: 08/27/24 12/16/24 MAI B DSC MW 02:20PM 04:05PM | AD21: 15 | AE21: 15 | AG21: =IF(RIGHT(C21,1)="L","Lab","Non-Lab") -> Non-Lab
A22: 2024FAL | B22: PSY | C22: 101 | D22: 02 | E22: Elementary Psychology I | F22: 4 | G22: Leckie | H22: Regina | K22: LeckieRegina | M22: M, W | N22: 1 | P22: 1 | U22: 1 | W22: =IF(S22=1,"MWF",IF(T22=1,"TR","Other")) -> Other | X22: 02:20PM - 04:05PM | Y22: 0.59722222 | Z22: 0.67013889 | AA22: D-P | AB22: 200 | AC22: 08/27/24 12/16/24 D-P 200 LEC MW 02:20PM 04:05PM | AD22: 25 | AE22: 26 | AG22: =IF(RIGHT(C22,1)="L","Lab","Non-Lab") -> Non-Lab
A23: 2024FAL | B23: REL | C23: 207 | D23: 01 | E23: Intro to Buddhism | F23: 4 | G23: Solovieva | H23: Olga | K23: SolovievaOlga | M23: M, W | N23: 1 | P23: 1 | U23: 1 | W23: =IF(S23=1,"MWF",IF(T23=1,"TR","Other")) -> Other | X23: 02:20PM - 04:05PM | Y23: 0.59722222 | Z23: 0.67013889 | AA23: MAI | AB23: 407 | AC23: 08/27/24 12/16/24 MAI 407 DSC MW 02:20PM 04:05PM | AD23: 20 | AE23: 13 | AG23: =IF(RIGHT(C23,1)="L","Lab","Non-Lab") -> Non-Lab
A24: 2024FAL | B24: CIS | C24: 280 | D24: 01 | E24: Scripting Languages | F24: 4 | G24: Thoma | H24: Cory | K24: ThomaCory | M24: M, W | N24: 1 | P24: 1 | U24: 1 | W24: =IF(S24=1,"MWF",IF(T24=1,"TR","Other")) -> Other | X24: 03:40PM - 05:25PM | Y24: 0.65277778 | Z24: 0.72569444 | AA24: TEK | AB24: 215 | AC24: 08/27/24 12/16/24 TEK 215 LEC MW 03:40PM 05:25PM | AD24: 16 | AE24: 14 | AG24: =IF(RIGHT(C24,1)="L","Lab","Non-Lab") -> Non-Lab
A25: 2024FAL | B25: PHL | C25: 450 | D25: 01 | E25: Research Seminar in Philosophy | F25: 4 | G25: Wolf | H25: Michael | K25: WolfMichael | M25: M, W | N25: 1 | P25: 1 | U25: 1 | W25: =IF(S25=1,"MWF",IF(T25=1,"TR","Other")) -> Other | X25: 03:40PM - 05:25PM | Y25: 0.65277778 | Z25: 0.72569444 | AA25: MAI | AB25: 404 | AC25: 08/27/24 12/16/24 MAI 404 SEM MW 03:40PM 05:25PM | AD25: 10 | AE25: 3 | AG25: =IF(RIGHT(C25,1)="L","Lab","Non-Lab") -> Non-Lab
A26: 2024FAL | B26: MUA | C26: 201 | D26: 01 | E26: Camerata Singers | F26: 1 | G26: Medley | H26: Susan | K26: MedleySusan | M26: M, W | N26: 1 | P26: 1 | U26: 1 | W26: =IF(S26=1,"MWF",IF(T26=1,"TR","Other")) -> Other | X26: 04:00PM - 05:25PM | Y26: 0.66666667 | Z26: 0.72569444 | AA26: OLN | AB26: 211 | AC26: 08/27/24 12/16/24 OLN 211 APP MW 04:00PM 05:25PM | AD26: 0 | AE26: 14 | AG26: =IF(RIGHT(C26,1)="L","Lab","Non-Lab") -> Non-Lab
A27: 2024FAL | B27: MUA | C27: 211 | D27: 01 | E27: Jazz Ensemble | F27: 1 | G27: Kahle | H27: Michael | I27: Swift | J27: Mark | K27: KahleMichael | L27: SwiftMark | M27: M, W | N27: 1 | P27: 1 | U27: 1 | W27: =IF(S27=1,"MWF",IF(T27=1,"TR","Other")) -> Other | X27: 05:45PM - 07:00PM | Y27: 0.73958333 | Z27: 0.79166667 | AA27: OLN | AB27: 211 | AC27: 08/27/24 12/16/24 OLN 211 APP MW 05:45PM 07:00PM | AD27: 30 | AE27: 15 | AG27: =IF(RIGHT(C27,1)="L","Lab","Non-Lab") -> Non-Lab
A28: 2024FAL | B28: MUA | C28: 111 | D28: 01 | E28: Wind Ensemble | F28: 1 | G28: Kahle | H28: Michael | I28: Swift | J28: Mark | K28: KahleMichael | L28: SwiftMark | M28: M, W | N28: 1 | P28: 1 | U28: 1 | W28: =IF(S28=1,"MWF",IF(T28=1,"TR","Other")) -> Other | X28: 07:10PM - 08:30PM | Y28: 0.79861111 | Z28: 0.85416667 | AA28: OLN | AB28: 211 | AC28: 08/27/24 12/16/24 OLN 211 APP MW 07:10PM 08:30PM | AD28: 50 | AE28: 22 | AG28: =IF(RIGHT(C28,1)="L","Lab","Non-Lab") -> Non-Lab
A29: 2024FAL | B29: PHA | C29: 104 | D29: 01 | E29: Fitness | F29: 2 | G29: Lesako | H29: Mark | I29: Glock | J29: Carol | K29: LesakoMark | L29: GlockCarol | M29: M, W | N29: 1 | P29: 1 | U29: 1 | W29: =IF(S29=1,"MWF",IF(T29=1,"TR","Other")) -> Other | X29: 09:00AM - 10:00AM | Y29: 0.375 | Z29: 0.41666667 | AA29: OGM | AB29: WELLCTR | AC29: 08/27/24 12/16/24 OGM WELLCTR ACT MW 09:00AM 10:00AM | AD29: 25 | AE29: 10 | AG29: =IF(RIGHT(C29,1)="L","Lab","Non-Lab") -> Non-Lab
A30: 2024FAL | B30: PHA | C30: 116 | D30: 01 | E30: Introduction to Yoga | F30: 2 | G30: Spadaro | H30: Patricia | I30: Glock | J30: Carol | K30: SpadaroPatricia | L30: GlockCarol | M30: M, W | N30: 1 | P30: 1 | U30: 1 | W30: =IF(S30=1,"MWF",IF(T30=1,"TR","Other")) -> Other | X30: 09:00AM - 10:00AM | Y30: 0.375 | Z30: 0.41666667 | AA30: REC | AB30: 304 | AC30: 08/27/24 12/16/24 REC 304 ACT MW 09:00AM 10:00AM | AD30: 20 | AE30: 19 | AG30: =IF(RIGHT(C30,1)="L","Lab","Non-Lab") -> Non-Lab
A31: 2024FAL | B31: ART | C31: 112 | D31: 03 | E31: Beginning Drawing | F31: 4 | G31: Schmidt | H31: Patrick | K31: SchmidtPatrick | M31: M, W | N31: 1 | P31: 1 | U31: 1 | W31: =IF(S31=1,"MWF",IF(T31=1,"TR","Other")) -> Other | X31: 09:00AM - 11:30AM | Y31: 0.375 | Z31: 0.47916667 | AA31: OLN | AB31: 219 | AC31: 08/27/24 12/16/24 OLN 219 STU MW 09:00AM 11:30AM | AD31: 10 | AE31: 10 | AG31: =IF(RIGHT(C31,1)="L","Lab","Non-Lab") -> Non-Lab
A32: 2024FAL | B32: PHA | C32: 126 | D32: 01 | E32: Pract Self Def Martial Arts | F32: 2 | G32: Mastascusa | H32: Mark | I32: Glock | J32: Carol | K32: MastascusaMark | L32: GlockCarol | M32: M, W | N32: 1 | P32: 1 | U32: 1 | W32: =IF(S32=1,"MWF",IF(T32=1,"TR","Other")) -> Other | X32: 10:20AM - 11:20AM | Y32: 0.43055556 | Z32: 0.47222222 | AA32: WSH | AB32: KUNGFU | AC32: 08/27/24 12/16/24 WSH KUNGFU ACT MW 10:20AM 11:20AM | AD32: 16 | AE32: 6 | AG32: =IF(RIGHT(C32,1)="L","Lab","Non-Lab") -> Non-Lab
A33: 2024FAL | B33: PHW | C33: 142 | D33: 01 | E33: Yoga and Meditation | F33: 2 | G33: Spadaro | H33: Patricia | I33: Glock | J33: Carol | K33: SpadaroPatricia | L33: GlockCarol | M33: M, W | N33: 1 | P33: 1 | U33: 1 | W33: =IF(S33=1,"MWF",IF(T33=1,"TR","Other")) -> Other | X33: 10:20AM - 11:20AM | Y33: 0.43055556 | Z33: 0.47222222 | AA33: REC | AB33: 304 | AC33: 08/27/24 12/16/24 REC 304 ACT MW 10:20AM 11:20AM | AD33: 20 | AE33: 20 | AG33: =IF(RIGHT(C33,1)="L","Lab","Non-Lab") -> Non-Lab
A34: 2024FAL | B34: ACC | C34: 211 | D34: 02 | E34: Financial Accounting | F34: 4 | G34: Mialki | H34: Dana | K34: MialkiDana | M34: M, W, F | N34: 1 | P34: 1 | R34: 1 | S34: 1 | W34: =IF(S34=1,"MWF",IF(T34=1,"TR","Other")) -> MWF | X34: 01:00PM - 02:10PM | Y34: 0.54166667 | Z34: 0.59027778 | AA34: BUR | AB34: 307 | AC34: 08/27/24 12/16/24 BUR 307 LEC MWF01:00PM 02:10PM | AD34: 25 | AE34: 30 | AG34: =IF(RIGHT(C34,1)="L","Lab","Non-Lab") -> Non-Lab
A35: 2024FAL | B35: ACC | C35: 346 | D35: 01 | E35: Cost & Adv Managerial Acct | F35: 4 | G35: Heggen | H35: Alexander | K35: HeggenAlexander | M35: M, W, F | N35: 1 | P35: 1 | R35: 1 | S35: 1 | W35: =IF(S35=1,"MWF",IF(T35=1,"TR","Other")) -> MWF | X35: 01:00PM - 02:10PM | Y35: 0.54166667 | Z35: 0.59027778 | AA35: BUR | AB35: 303 | AC35: 08/27/24 12/16/24 BUR 303 LEC MWF01:00PM 02:10PM | AD35: 30 | AE35: 17 | AG35: =IF(RIGHT(C35,1)="L","Lab","Non-Lab") -> Non-Lab
A36: 2024FAL | B36: BIO | C36: 100 | D36: 01 | E36: Intro to Bioinformatics | F36: 4 | G36: Hansen | H36: Casey | K36: HansenCasey | M36: M, W, F | N36: 1 | P36: 1 | R36: 1 | S36: 1 | W36: =IF(S36=1,"MWF",IF(T36=1,"TR","Other")) -> MWF | X36: 01:00PM - 02:10PM | Y36: 0.54166667 | Z36: 0.59027778 | AA36: D-P | AB36: 311 | AC36: 08/27/24 12/16/24 D-P 311 LEC MWF 01:00PM 02:10PM | AD36: 8 | AE36: 8 | AF36: 27483, 27484 | AG36: =IF(RIGHT(C36,1)="L","Lab","Non-Lab") -> Non-Lab
A37: 2024FAL | B37: BIO | C37: 103 | D37: 01 | E37: Human Anatomy & Physiology I | F37: 4 | G37: Emerson | H37: Kyle | K37: EmersonKyle | M37: M, W, F | N37: 1 | P37: 1 | R37: 1 | S37: 1 | W37: =IF(S37=1,"MWF",IF(T37=1,"TR","Other")) -> MWF | X37: 01:00PM - 02:10PM | Y37: 0.54166667 | Z37: 0.59027778 | AA37: D-P | AB37: 100 | AC37: 08/27/24 12/16/24 D-P 100 LEC MWF 01:00PM 02:10PM | AD37: 24 | AE37: 37 | AG37: =IF(RIGHT(C37,1)="L","Lab","Non-Lab") -> Non-Lab
A38: 2024FAL | B38: BIO | C38: 247 | D38: 01 | E38: Intro to Bioinformatics | F38: 4 | G38: Hansen | H38: Casey | K38: HansenCasey | M38: M, W, F | N38: 1 | P38: 1 | R38: 1 | S38: 1 | W38: =IF(S38=1,"MWF",IF(T38=1,"TR","Other")) -> MWF | X38: 01:00PM - 02:10PM | Y38: 0.54166667 | Z38: 0.59027778 | AA38: D-P | AB38: 311 | AC38: 08/27/24 12/16/24 D-P 311 LEC MWF 01:00PM 02:10PM | AD38: 8 | AE38: 2 | AF38: 27483, 27484 | AG38: =IF(RIGHT(C38,1)="L","Lab","Non-Lab") -> Non-Lab
A39: 2024FAL | B39: BIO | C39: 311 | D39: 01 | E39: Molecular Biology | F39: 4 | G39: Lohr | H39: Kelly | K39: LohrKelly | M39: M, W, F | N39: 1 | P39: 1 | R39: 1 | S39: 1 | W39: =IF(S39=1,"MWF",IF(T39=1,"TR","Other")) -> MWF | X39: 01:00PM - 02:10PM | Y39: 0.54166667 | Z39: 0.59027778 | AA39: D-P | AB39: 106 | AC39: 08/27/24 12/16/24 D-P 106 LEC MWF 01:00PM 02:10PM | AD39: 16 | AE39: 16 | AG39: =IF(RIGHT(C39,1)="L","Lab","Non-Lab") -> Non-Lab
A40: 2024FAL | B40: BUS | C40: 101 | D40: 01 | E40: Bus, Entrepreneurship & Societ | F40: 4 | G40: Miller | H40: Max | K40: MillerMax | M40: M, W, F | N40: 1 | P40: 1 | R40: 1 | S40: 1 | W40: =IF(S40=1,"MWF",IF(T40=1,"TR","Other")) -> MWF | X40: 01:00PM - 02:10PM | Y40: 0.54166667 | Z40: 0.59027778 | AA40: BUR | AB40: 114 | AC40: 08/27/24 12/16/24 BUR 114 LEC MWF01:00PM 02:10PM | AD40: 30 | AE40: 36 | AG40: =IF(RIGHT(C40,1)="L","Lab","Non-Lab") -> Non-Lab
...

Sheet Coin Flip
B2: P | C2: 0.03664 | F2: Amount to play | G2: 10 | I2: Payout Ratio
B3: 1-P | C3: =1-C2 -> 0.96336 | F3: Paid to Winner | G3: -1000 | I3: =G2/G3 -> -0.01
F4: Paid to Loser | G4: 0
P8: Game # | Q8: Result | R8: Cash received | S8: Cash Paid | T8: Per-play cash flow | U8: Total CF
P9: {=_xlfn.SEQUENCE(10000)} -> 1 | Q9: =IF(RAND()<$C$2,1,0) -> 0 | R9: =$G$2 -> 10 | S9: =IF(Q9=1,$G$3,$G$4) -> 0 | T9: =R9+S9 -> 10 | U9: =SUM($R$9:S9) -> 10
P10: 2 | Q10: =IF(RAND()<$C$2,1,0) -> 0 | R10: =$G$2 -> 10 | S10: =IF(Q10=1,$G$3,$G$4) -> 0 | T10: =R10+S10 -> 10 | U10: =SUM($R$9:S10) -> 20
P11: 3 | Q11: =IF(RAND()<$C$2,1,0) -> 0 | R11: =$G$2 -> 10 | S11: =IF(Q11=1,$G$3,$G$4) -> 0 | T11: =R11+S11 -> 10 | U11: =SUM($R$9:S11) -> 30
P12: 4 | Q12: =IF(RAND()<$C$2,1,0) -> 0 | R12: =$G$2 -> 10 | S12: =IF(Q12=1,$G$3,$G$4) -> 0 | T12: =R12+S12 -> 10 | U12: =SUM($R$9:S12) -> 40
P13: 5 | Q13: =IF(RAND()<$C$2,1,0) -> 0 | R13: =$G$2 -> 10 | S13: =IF(Q13=1,$G$3,$G$4) -> 0 | T13: =R13+S13 -> 10 | U13: =SUM($R$9:S13) -> 50
P14: 6 | Q14: =IF(RAND()<$C$2,1,0) -> 0 | R14: =$G$2 -> 10 | S14: =IF(Q14=1,$G$3,$G$4) -> 0 | T14: =R14+S14 -> 10 | U14: =SUM($R$9:S14) -> 60
P15: 7 | Q15: =IF(RAND()<$C$2,1,0) -> 1 | R15: =$G$2 -> 10 | S15: =IF(Q15=1,$G$3,$G$4) -> -1000 | T15: =R15+S15 -> -990 | U15: =SUM($R$9:S15) -> -930
P16: 8 | Q16: =IF(RAND()<$C$2,1,0) -> 0 | R16: =$G$2 -> 10 | S16: =IF(Q16=1,$G$3,$G$4) -> 0 | T16: =R16+S16 -> 10 | U16: =SUM($R$9:S16) -> -920
P17: 9 | Q17: =IF(RAND()<$C$2,1,0) -> 0 | R17: =$G$2 -> 10 | S17: =IF(Q17=1,$G$3,$G$4) -> 0 | T17: =R17+S17 -> 10 | U17: =SUM($R$9:S17) -> -910
P18: 10 | Q18: =IF(RAND()<$C$2,1,0) -> 0 | R18: =$G$2 -> 10 | S18: =IF(Q18=1,$G$3,$G$4) -> 0 | T18: =R18+S18 -> 10 | U18: =SUM($R$9:S18) -> -900
P19: 11 | Q19: =IF(RAND()<$C$2,1,0) -> 0 | R19: =$G$2 -> 10 | S19: =IF(Q19=1,$G$3,$G$4) -> 0 | T19: =R19+S19 -> 10 | U19: =SUM($R$9:S19) -> -890
P20: 12 | Q20: =IF(RAND()<$C$2,1,0) -> 0 | R20: =$G$2 -> 10 | S20: =IF(Q20=1,$G$3,$G$4) -> 0 | T20: =R20+S20 -> 10 | U20: =SUM($R$9:S20) -> -880
P21: 13 | Q21: =IF(RAND()<$C$2,1,0) -> 0 | R21: =$G$2 -> 10 | S21: =IF(Q21=1,$G$3,$G$4) -> 0 | T21: =R21+S21 -> 10 | U21: =SUM($R$9:S21) -> -870
... P10008: 10000 | Q10008: =IF(RAND()<$C$2,1,0) -> 0 | R10008: =$G$2 -> 10 | S10008: =IF(Q10008=1,$G$3,$G$4) -> 0 | T10008: =R10008+S10008 -> 10 | U10008: =SUM($R$9:S10008) -> -259000

Sheet Blocks
B3: FV | E3: NPER | H3: PMT
B4: RATE | C4: 0.0475 | E4: RATE | F4: 0.05 | H4: RATE | I4: 0.0475
B5: NPER | C5: 1 | H5: NPER | I5: 1
B6: PMT | C6: 0 | E6: PMT | F6: 0 | H6: PMT | I6: 0
B7: PV | C7: -1000 | E7: PV | F7: -1000 | H7: PV | I7: -1000
E8: FV | F8: 1221
B10: Time Adj | C10: 12 | E10: Time Adj | F10: 12 | H10: Time Adj | I10: 12
B12: Time Adj Rate | C12: =C4/C10 -> 0.0039583333 | E12: Time Adj Rate | F12: =F4/F10 -> 0.0041666667 | H12: Time Adj Rate | I12: =I4/I10 -> 0.0039583333
B13: Time Adj NPER | C13: =C5*C10 -> 12 | E13: Time Adj NPER | F13: =F5*F10 -> 0 | H13: Time Adj NPER | I13: =I5*I10 -> 12
B15: FV | C15: =FV(C12,C13,C6,C7) -> 1048.5479 | E15: NPER | F15: =NPER(F4,F6,F7,F8) -> 4.0924272 | H15: FV | I15: =FV(I12,I13,I6,I7) -> 1048.5479
B19: RATE | E19: PV
B20: NPER | C20: 4 | E20: RATE | F20: 0.0475
B21: PMT | C21: 1 | E21: NPER | F21: 1
B22: PV | C22: -1048.55 | E22: PMT | F22: 0
B23: FV | C23: 1221 | E23: PV | F23: -1000
B26: Time Adj | C26: 12 | E26: Time Adj | F26: 12
B28: Time Adj Rate | C28: =C20/C26 -> 0.33333333 | E28: Time Adj Rate | F28: =F20/F26 -> 0.0039583333
B29: Time Adj NPER | C29: =C26*C20 -> 48 | E29: Time Adj NPER | F29: =F21*F26 -> 12
B31: RATE | C31: =RATE(C20,C21,C22,C23) -> 0.039700878 | E31: FV | F31: =FV(F28,F29,F22,F23) -> 1048.5479
B35: make sure you have 5 blocks and they are cleaned up

Sheet Cheat sheet
A1: Investmentment decision
A3: initial investment
A4: answer to the question (make sure it is detailed, so you can restate the problem)
O6: graph over here
A7: crate a lst for initial tenor
A9: pmt could be off th page
A11: make sure you annotate and explain
D23: goes into properties and makes sure its yours
D24: you can right click on a tab and do move or copy then move it to your workbook
D25: formatting is very important shouldn't have numbers keyed into functions
D26: clean up things like the axis in the course catalouge file
D27: try a 3D way to present the schedule to where you could see evertything
D28: make sure to tell a story, make it up if you need to (best way to filter and look at the data)
D29: the question is: how can we visualize the problem in the best way
D30: Don’t lead with the calculations, just have them at the bottom of the sheet

Sheet Odds
C5: American Odds | E5: P
C6: -425 | E6: =-C6/(100-C6) -> 0.80952381 | F6: =_xlfn.FORMULATEXT(E6) -> =-C6/(100-C6)
C8: 330 | E8: =100/(100+C8) -> 0.23255814 | F8: =_xlfn.FORMULATEXT(E8) -> =100/(100+C8)
E10: =E6+E8 -> 1.0420819

Sheet H or T 
B2: P | C2: 0.5
B3: 1-P | C3: =1-C2 -> 0.5
B5: {=_xlfn.SEQUENCE(1000)} -> 1 | C5: =IF(RAND()<$C$2,"H","T") -> T | E5: H
B6: 2 | C6: =IF(RAND()<$C$2,"H","T") -> T
B7: 3 | C7: =IF(RAND()<$C$2,"H","T") -> H | E7: =COUNTIFS(C5:C1004,"="&E5) -> 491 | F7: =_xlfn.FORMULATEXT(E7) -> =COUNTIFS(C5:C1004,"="&E5)
B8: 4 | C8: =IF(RAND()<$C$2,"H","T") -> H
B9: 5 | C9: =IF(RAND()<$C$2,"H","T") -> H
B10: 6 | C10: =IF(RAND()<$C$2,"H","T") -> T
B11: 7 | C11: =IF(RAND()<$C$2,"H","T") -> T
B12: 8 | C12: =IF(RAND()<$C$2,"H","T") -> H
B13: 9 | C13: =IF(RAND()<$C$2,"H","T") -> H
B14: 10 | C14: =IF(RAND()<$C$2,"H","T") -> T
B15: 11 | C15: =IF(RAND()<$C$2,"H","T") -> H
B16: 12 | C16: =IF(RAND()<$C$2,"H","T") -> T
B17: 13 | C17: =IF(RAND()<$C$2,"H","T") -> H
B18: 14 | C18: =IF(RAND()<$C$2,"H","T") -> T
B19: 15 | C19: =IF(RAND()<$C$2,"H","T") -> H
... B1004: 1000 | C1004: =IF(RAND()<$C$2,"H","T") -> T

Sheet Solataire
J2: =_xlfn.FORMULATEXT(J3) -> =MIN(J6:J57) | K2: =_xlfn.FORMULATEXT(K3) -> =SUM(K8:K57)
B3: Simulations | C3: 1000 | J3: =MIN(J6:J57) -> 3 | K3: =SUM(K8:K57) -> 0
J4: =_xlfn.FORMULATEXT(J6) -> =IF(B6=G6,A6,"") | K4: =_xlfn.FORMULATEXT(K8) -> =(IF(AND(G8=G7,G7=G6,SUM($J$6:J8)=0),1,0))
B5: Call Order | D5: Deck Cards | E5: Random | G5: Shuffled Deck | H5: Rand Sorted | J5: Solitaire Check | K5: 3 in a Row Check
A6: 1 | B6: 1 | D6: 1 | E6: =RAND()*10000000 -> 7115074.7 | G6: {=_xlfn.SORTBY(D6:E57,E6:E57)} -> 13 | H6: 33298.977 | J6: =IF(B6=G6,A6,"") | N6: 19 | O6: 0
A7: 2 | B7: 2 | D7: 2 | E7: =RAND()*10000000 -> 8931513.5 | G7: 5 | H7: 163702.31 | J7: =IF(B7=G7,A7,"") | N7: 13 | O7: 0
A8: 3 | B8: 3 | D8: 3 | E8: =RAND()*10000000 -> 7543592.7 | G8: 3 | H8: 422790.69 | J8: =IF(B8=G8,A8,"") -> 3 | K8: =(IF(AND(G8=G7,G7=G6,SUM($J$6:J8)=0),1,0)) -> 0 | N8: 1 | O8: 0
A9: 4 | B9: 4 | D9: 4 | E9: =RAND()*10000000 -> 3068064 | G9: 2 | H9: 437971.76 | J9: =IF(B9=G9,A9,"") | K9: =(IF(AND(G9=G8,G8=G7,SUM($J$6:J9)=0),1,0)) -> 0 | N9: 33 | O9: 0
A10: 5 | B10: 5 | D10: 5 | E10: =RAND()*10000000 -> 3154428.8 | G10: 2 | H10: 486954.02 | J10: =IF(B10=G10,A10,"") | K10: =(IF(AND(G10=G9,G9=G8,SUM($J$6:J10)=0),1,0)) -> 0 | N10: 35 | O10: 0
A11: 6 | B11: 6 | D11: 6 | E11: =RAND()*10000000 -> 3161945.1 | G11: 9 | H11: 722776.81 | J11: =IF(B11=G11,A11,"") | K11: =(IF(AND(G11=G10,G10=G9,SUM($J$6:J11)=0),1,0)) -> 0 | N11: 2 | O11: 0
A12: 7 | B12: 7 | D12: 7 | E12: =RAND()*10000000 -> 1041555.8 | G12: 5 | H12: 731887.56 | J12: =IF(B12=G12,A12,"") | K12: =(IF(AND(G12=G11,G11=G10,SUM($J$6:J12)=0),1,0)) -> 0 | N12: 20 | O12: 0
A13: 8 | B13: 8 | D13: 8 | E13: =RAND()*10000000 -> 2818907.9 | G13: 4 | H13: 968240.86 | J13: =IF(B13=G13,A13,"") | K13: =(IF(AND(G13=G12,G12=G11,SUM($J$6:J13)=0),1,0)) -> 0 | N13: 0 | O13: 0
A14: 9 | B14: 9 | D14: 9 | E14: =RAND()*10000000 -> 8935026.4 | G14: 1 | H14: 1005789 | J14: =IF(B14=G14,A14,"") | K14: =(IF(AND(G14=G13,G13=G12,SUM($J$6:J14)=0),1,0)) -> 0 | N14: 3 | O14: 0
A15: 10 | B15: 10 | D15: 10 | E15: =RAND()*10000000 -> 9780622.2 | G15: 7 | H15: 1041555.8 | J15: =IF(B15=G15,A15,"") | K15: =(IF(AND(G15=G14,G14=G13,SUM($J$6:J15)=0),1,0)) -> 0 | N15: 15 | O15: 0
A16: 11 | B16: 11 | D16: 11 | E16: =RAND()*10000000 -> 3743936.9 | G16: 3 | H16: 1186803.9 | J16: =IF(B16=G16,A16,"") | K16: =(IF(AND(G16=G15,G15=G14,SUM($J$6:J16)=0),1,0)) -> 0 | N16: 3 | O16: 0
A17: 12 | B17: 12 | D17: 12 | E17: =RAND()*10000000 -> 6657114 | G17: 12 | H17: 1330049.7 | J17: =IF(B17=G17,A17,"") -> 12 | K17: =(IF(AND(G17=G16,G16=G15,SUM($J$6:J17)=0),1,0)) -> 0 | N17: 8 | O17: 0
A18: 13 | B18: 13 | D18: 13 | E18: =RAND()*10000000 -> 9406884.6 | G18: 13 | H18: 1462934.2 | J18: =IF(B18=G18,A18,"") -> 13 | K18: =(IF(AND(G18=G17,G17=G16,SUM($J$6:J18)=0),1,0)) -> 0 | N18: 16 | O18: 0
A19: 14 | B19: 1 | D19: 1 | E19: =RAND()*10000000 -> 3439672.6 | G19: 6 | H19: 1829681.8 | J19: =IF(B19=G19,A19,"") | K19: =(IF(AND(G19=G18,G18=G17,SUM($J$6:J19)=0),1,0)) -> 0 | N19: 31 | O19: 0
... A57: 52 | B57: 13 | D57: 13 | E57: =RAND()*10000000 -> 2054357.8 | G57: 10 | H57: 9780622.2 | J57: =IF(B57=G57,A57,"") | K57: =(IF(AND(G57=G56,G56=G55,SUM($J$6:J57)=0),1,0)) -> 0 | N57: 31 | O57: 0
N58: 5 | O58: 0
N59: 3 | O59: 0
N60: 1 | O60: 0
N61: 5 | O61: 0
N62: 7 | O62: 0
N63: 0 | O63: 0
N64: 3 | O64: 0
N65: 3 | O65: 0
N66: 7 | O66: 0
N67: 11 | O67: 0
N68: 2 | O68: 0
N69: 9 | O69: 0
... N1005: 12 | O1005: 0
